<?xml version='1.0' encoding='utf-8'?>
<robot name="biped_s52">
  <mujoco>
    <compiler meshdir="../meshes/" balanceinertia="true" discardvisual="false" />
  </mujoco>
  <link name="base_link">
    <inertial>
      <origin xyz="-0.05051209 1.42e-06 -0.01248997" rpy="0 0 0" />
      <mass value="6.48663928" />
      <inertia ixx="0.06836878" ixy="1.858e-05" ixz="-0.0165872" iyy="0.04966552" iyz="-1.2e-05" izz="0.06645264" />
    </inertial>
    <visual>
      <origin xyz="0 0 0" rpy="0 0 0" />
      <geometry>
        <mesh filename="../../meshes/base_link.STL" />
      </geometry>
      <material name="">
        <color rgba="1 1 1 1" />
      </material>
    </visual>
  </link>
  <link name="waist_yaw_link">
    <inertial>
      <origin xyz="0.00089444 -0.00069446 0.16778314" rpy="0 0 0" />
      <mass value="18.01415568" />
      <inertia ixx="0.36258863" ixy="1.968e-05" ixz="0.00273234" iyy="0.27799251" iyz="0.00088683" izz="0.21591828" />
    </inertial>
    <visual>
      <origin xyz="0 0 0" rpy="0 0 0" />
      <geometry>
        <mesh filename="../../meshes/waist_yaw.STL" />
      </geometry>
      <material name="">
        <color rgba="1 1 1 1" />
      </material>
    </visual>
  </link>
  <joint name="waist_yaw_joint" type="fixed">
    <origin xyz="0 0 0.1114" rpy="0 0 0" />
    <parent link="base_link" />
    <child link="waist_yaw_link" />
    <axis xyz="0 0 1" />
    <limit lower="-3.14159" upper="3.14159" effort="180.0" velocity="23.55" />
  </joint>
  <link name="zarm_l1_link">
    <inertial>
      <origin xyz="0.00166796 0.07275896 0.00012987" rpy="0 0 0" />
      <mass value="0.91653322" />
      <inertia ixx="0.00126587" ixy="1.362e-05" ixz="-2e-05" iyy="0.00086921" iyz="1e-05" izz="0.00124337" />
    </inertial>
    <visual>
      <origin xyz="0 0 0" rpy="0 0 0" />
      <geometry>
        <mesh filename="../../meshes/l_arm_pitch.STL" />
      </geometry>
      <material name="">
        <color rgba="1 1 1 1" />
      </material>
    </visual>
  </link>
  <joint name="zarm_l1_joint" type="revolute">
    <origin xyz="-0.003 0.2547 0.2831" rpy="0 0 0" />
    <parent link="waist_yaw_link" />
    <child link="zarm_l1_link" />
    <axis xyz="0 1 0" />
    <limit lower="-2.4" upper="0.6" effort="100.0" velocity="41.3433333333333" />
    <dynamics damping="0.2" friction="0.0" />
  </joint>
  <link name="zarm_l2_link">
    <inertial>
      <origin xyz="-0.00080932 6.91e-06 -0.04651" rpy="0 0 0" />
      <mass value="0.3876739" />
      <inertia ixx="0.0008074" ixy="-1.1e-05" ixz="-2.196e-05" iyy="0.00116146" iyz="-1.4e-05" izz="0.00070225" />
    </inertial>
    <visual>
      <origin xyz="0 0 0" rpy="0 0 0" />
      <geometry>
        <mesh filename="../../meshes/l_arm_roll.STL" />
      </geometry>
      <material name="">
        <color rgba="1 1 1 1" />
      </material>
    </visual>
  </link>
  <joint name="zarm_l2_joint" type="revolute">
    <origin xyz="0 0 0" rpy="0 0 0" />
    <parent link="zarm_l1_link" />
    <child link="zarm_l2_link" />
    <axis xyz="1 0 0" />
    <limit lower="-0.349065850398866" upper="1.46" effort="50.0" velocity="19.154" />
    <dynamics damping="0.2" friction="0.0" />
  </joint>
  <link name="zarm_l3_link">
    <inertial>
      <origin xyz="0.00943019 0.00343988 -0.11304538" rpy="0 0 0" />
      <mass value="1.77926875" />
      <inertia ixx="0.00992856" ixy="-7.192e-05" ixz="0.00107196" iyy="0.01004582" iyz="0.00040685" izz="0.00185422" />
    </inertial>
    <visual>
      <origin xyz="0 0 0" rpy="0 0 0" />
      <geometry>
        <mesh filename="../../meshes/l_arm_yaw.STL" />
      </geometry>
      <material name="">
        <color rgba="1 1 1 1" />
      </material>
    </visual>
  </link>
  <joint name="zarm_l3_joint" type="revolute">
    <origin xyz="0 0 -0.104" rpy="0 0 0" />
    <parent link="zarm_l2_link" />
    <child link="zarm_l3_link" />
    <axis xyz="0 0 1" />
    <limit lower="-1.5707963267949" upper="0.46" effort="39.0" velocity="18.84" />
    <dynamics damping="0.2" friction="0.0" />
  </joint>
  <link name="zarm_l4_link">
    <inertial>
      <origin xyz="-0.01829932 0.00087167 -0.06936622" rpy="0 0 0" />
      <mass value="0.58507821" />
      <inertia ixx="0.00143291" ixy="-4.8e-05" ixz="-0.00011641" iyy="0.00125018" iyz="-2.018e-05" izz="0.00068356" />
    </inertial>
    <visual>
      <origin xyz="0 0 0" rpy="0 0 0" />
      <geometry>
        <mesh filename="../../meshes/l_forearm.STL" />
      </geometry>
      <material name="">
        <color rgba="1 1 1 1" />
      </material>
    </visual>
  </link>
  <joint name="zarm_l4_joint" type="revolute">
    <origin xyz="0.02 0 -0.1797" rpy="0 0 0" />
    <parent link="zarm_l3_link" />
    <child link="zarm_l4_link" />
    <axis xyz="0 1 0" />
    <limit lower="-2.61799387799149" upper="0.0" effort="50.0" velocity="18.84" />
    <dynamics damping="0.2" friction="0.0" />
  </joint>
  <link name="zarm_l5_link">
    <inertial>
      <origin xyz="-0.0102609 1.322e-05 -0.06083944" rpy="0 0 0" />
      <mass value="0.68679955" />
      <inertia ixx="0.00086873" ixy="1.2e-05" ixz="-8.786e-05" iyy="0.00122518" iyz="-1.1e-05" izz="0.00066873" />
    </inertial>
    <visual>
      <origin xyz="0 0 0" rpy="0 0 0" />
      <geometry>
        <mesh filename="../../meshes/l_hand_yaw.STL" />
      </geometry>
      <material name="">
        <color rgba="1 1 1 1" />
      </material>
    </visual>
  </link>
  <joint name="zarm_l5_joint" type="revolute">
    <origin xyz="-0.02 0 -0.1195" rpy="0 0 0" />
    <parent link="zarm_l4_link" />
    <child link="zarm_l5_link" />
    <axis xyz="0 0 1" />
    <limit lower="-1.5707963267949" upper="1.5707963267949" effort="12.0" velocity="21.666" />
    <dynamics damping="0.2" friction="0.0" />
  </joint>
  <link name="zarm_l6_link">
    <inertial>
      <origin xyz="0.00019162 0.00886363 -0.01747746" rpy="0 0 0" />
      <mass value="0.39387181" />
      <inertia ixx="0.00018535" ixy="7.5e-05" ixz="-4.6e-05" iyy="0.00019853" iyz="5e-05" izz="0.0002021" />
    </inertial>
    <visual>
      <origin xyz="0 0 0" rpy="0 0 0" />
      <geometry>
        <mesh filename="../../meshes/l_hand_roll.STL" />
      </geometry>
      <material name="">
        <color rgba="1 1 1 1" />
      </material>
    </visual>
  </link>
  <joint name="zarm_l6_joint" type="revolute">
    <origin xyz="0 0 -0.114" rpy="0 0 0" />
    <parent link="zarm_l5_link" />
    <child link="zarm_l6_link" />
    <axis xyz="1 0 0" />
    <limit lower="-1.30899693899575" upper="0.698131700797732" effort="12.0" velocity="21.666" />
    <dynamics damping="0.2" friction="0.0" />
  </joint>
  <link name="zarm_l7_link">
    <inertial>
      <origin xyz="0.00326402 0.0057645 -0.12230994" rpy="0 0 0" />
      <mass value="0.61537779" />
      <inertia ixx="0.00161739" ixy="1.846e-05" ixz="4.975e-05" iyy="0.00155413" iyz="-9.681e-05" izz="0.00018354" />
    </inertial>
    <visual>
      <origin xyz="0 0 0" rpy="0 0 0" />
      <geometry>
        <mesh filename="../../meshes/l_hand_pitch.STL" />
      </geometry>
      <material name="">
        <color rgba="1 1 1 1" />
      </material>
    </visual>
  </link>
  <joint name="zarm_l7_joint" type="revolute">
    <origin xyz="-0.0002 0 -0.021" rpy="0 0 0" />
    <parent link="zarm_l6_link" />
    <child link="zarm_l7_link" />
    <axis xyz="0 1 0" />
    <limit lower="-0.698131700797732" upper="0.698131700797732" effort="12.0" velocity="21.666" />
    <dynamics damping="0.2" friction="0.0" />
  </joint>
  <link name="zarm_l7_end_effector">
    <collision>
      <origin rpy="0 0 0" xyz="0 0 0" />
      <geometry>
        <sphere radius="0.005" />
      </geometry>
    </collision>
  </link>
  <joint name="zarm_l7_end_effector_joint" type="fixed">
    <origin xyz="0 -0.03 -0.17" rpy="0 0 0" />
    <parent link="zarm_l7_link" />
    <child link="zarm_l7_end_effector" />
  </joint>
  <link name="zarm_r1_link">
    <inertial>
      <origin xyz="0.00166796 -0.07275896 0.00012987" rpy="0 0 0" />
      <mass value="0.92062797" />
      <inertia ixx="0.00126587" ixy="1.362e-05" ixz="-2e-05" iyy="0.00086921" iyz="1e-05" izz="0.00124337" />
    </inertial>
    <visual>
      <origin xyz="0 0 0" rpy="0 0 0" />
      <geometry>
        <mesh filename="../../meshes/r_arm_pitch.STL" />
      </geometry>
      <material name="">
        <color rgba="1 1 1 1" />
      </material>
    </visual>
  </link>
  <joint name="zarm_r1_joint" type="revolute">
    <origin xyz="-0.003 -0.2547 0.2831" rpy="0 0 0" />
    <parent link="waist_yaw_link" />
    <child link="zarm_r1_link" />
    <axis xyz="0 1 0" />
    <limit lower="-2.4" upper="0.6" effort="100.0" velocity="41.3433333333333" />
    <dynamics damping="0.2" friction="0.0" />
  </joint>
  <link name="zarm_r2_link">
    <inertial>
      <origin xyz="-0.00080932 -6.91e-06 -0.04651" rpy="0 0 0" />
      <mass value="0.38768053" />
      <inertia ixx="0.0008074" ixy="-1.1e-05" ixz="-2.196e-05" iyy="0.00116146" iyz="-1.4e-05" izz="0.00070225" />
    </inertial>
    <visual>
      <origin xyz="0 0 0" rpy="0 0 0" />
      <geometry>
        <mesh filename="../../meshes/r_arm_roll.STL" />
      </geometry>
      <material name="">
        <color rgba="1 1 1 1" />
      </material>
    </visual>
  </link>
  <joint name="zarm_r2_joint" type="revolute">
    <origin xyz="0 0 0" rpy="0 0 0" />
    <parent link="zarm_r1_link" />
    <child link="zarm_r2_link" />
    <axis xyz="1 0 0" />
    <limit lower="-1.46" upper="0.349065850398866" effort="50.0" velocity="19.154" />
    <dynamics damping="0.2" friction="0.0" />
  </joint>
  <link name="zarm_r3_link">
    <inertial>
      <origin xyz="0.00933929 -0.00288519 -0.11324121" rpy="0 0 0" />
      <mass value="1.77969208" />
      <inertia ixx="0.00912947" ixy="5.935e-05" ixz="0.0010589" iyy="0.00911437" iyz="-0.0003408" izz="0.00118423" />
    </inertial>
    <visual>
      <origin xyz="0 0 0" rpy="0 0 0" />
      <geometry>
        <mesh filename="../../meshes/r_arm_yaw.STL" />
      </geometry>
      <material name="">
        <color rgba="1 1 1 1" />
      </material>
    </visual>
  </link>
  <joint name="zarm_r3_joint" type="revolute">
    <origin xyz="0 0 -0.104" rpy="0 0 0" />
    <parent link="zarm_r2_link" />
    <child link="zarm_r3_link" />
    <axis xyz="0 0 1" />
    <limit lower="-0.46" upper="1.5707963267949" effort="39.0" velocity="18.84" />
    <dynamics damping="0.2" friction="0.0" />
  </joint>
  <link name="zarm_r4_link">
    <inertial>
      <origin xyz="-0.01829785 -0.00087299 -0.06936486" rpy="0 0 0" />
      <mass value="0.58514611" />
      <inertia ixx="0.00137872" ixy="4.8e-05" ixz="-0.00011643" iyy="0.00119519" iyz="1.985e-05" izz="0.00061317" />
    </inertial>
    <visual>
      <origin xyz="0 0 0" rpy="0 0 0" />
      <geometry>
        <mesh filename="../../meshes/r_forearm.STL" />
      </geometry>
      <material name="">
        <color rgba="1 1 1 1" />
      </material>
    </visual>
  </link>
  <joint name="zarm_r4_joint" type="revolute">
    <origin xyz="0.02 0 -0.1797" rpy="0 0 0" />
    <parent link="zarm_r3_link" />
    <child link="zarm_r4_link" />
    <axis xyz="0 1 0" />
    <limit lower="-2.61799387799149" upper="0.0" effort="50.0" velocity="18.84" />
    <dynamics damping="0.2" friction="0.0" />
  </joint>
  <link name="zarm_r5_link">
    <inertial>
      <origin xyz="-0.01023461 -2.917e-05 -0.06078644" rpy="0 0 0" />
      <mass value="0.68473867" />
      <inertia ixx="0.00079741" ixy="-0.0001" ixz="-8.692e-05" iyy="0.00116896" iyz="9.7e-05" izz="0.00061233" />
    </inertial>
    <visual>
      <origin xyz="0 0 0" rpy="0 0 0" />
      <geometry>
        <mesh filename="../../meshes/r_hand_yaw.STL" />
      </geometry>
      <material name="">
        <color rgba="1 1 1 1" />
      </material>
    </visual>
  </link>
  <joint name="zarm_r5_joint" type="revolute">
    <origin xyz="-0.02 0 -0.1195" rpy="0 0 0" />
    <parent link="zarm_r4_link" />
    <child link="zarm_r5_link" />
    <axis xyz="0 0 1" />
    <limit lower="-1.5707963267949" upper="1.5707963267949" effort="12.0" velocity="21.666" />
    <dynamics damping="0.2" friction="0.0" />
  </joint>
  <link name="zarm_r6_link">
    <inertial>
      <origin xyz="0.00019291 -0.0089543 -0.01746466" rpy="0 0 0" />
      <mass value="0.39247462" />
      <inertia ixx="0.00013001" ixy="-7.7e-05" ixz="-4.5e-05" iyy="0.00012773" iyz="-4.8e-05" izz="0.00014597" />
    </inertial>
    <visual>
      <origin xyz="0 0 0" rpy="0 0 0" />
      <geometry>
        <mesh filename="../../meshes/r_hand_roll.STL" />
      </geometry>
      <material name="">
        <color rgba="1 1 1 1" />
      </material>
    </visual>
  </link>
  <joint name="zarm_r6_joint" type="revolute">
    <origin xyz="0 0 -0.114" rpy="0 0 0" />
    <parent link="zarm_r5_link" />
    <child link="zarm_r6_link" />
    <axis xyz="1 0 0" />
    <limit lower="-0.698131700797732" upper="1.30899693899575" effort="12.0" velocity="21.666" />
    <dynamics damping="0.2" friction="0.0" />
  </joint>
  <link name="zarm_r7_link">
    <inertial>
      <origin xyz="0.00330838 -0.00562282 -0.12209714" rpy="0 0 0" />
      <mass value="0.61562202" />
      <inertia ixx="0.00161739" ixy="-1.846e-05" ixz="4.975e-05" iyy="0.00155413" iyz="9.681e-05" izz="0.00018354" />
    </inertial>
    <visual>
      <origin xyz="0 0 0" rpy="0 0 0" />
      <geometry>
        <mesh filename="../../meshes/r_hand_pitch.STL" />
      </geometry>
      <material name="">
        <color rgba="1 1 1 1" />
      </material>
    </visual>
  </link>
  <joint name="zarm_r7_joint" type="revolute">
    <origin xyz="0 0 -0.022284" rpy="0 0 0" />
    <parent link="zarm_r6_link" />
    <child link="zarm_r7_link" />
    <axis xyz="0 1 0" />
    <limit lower="-0.698131700797732" upper="0.698131700797732" effort="12.0" velocity="21.666" />
    <dynamics damping="0.2" friction="0.0" />
  </joint>
  <link name="zarm_r7_end_effector">
    <collision>
      <origin rpy="0 0 0" xyz="0 0 0" />
      <geometry>
        <sphere radius="0.005" />
      </geometry>
    </collision>
  </link>
  <joint name="zarm_r7_end_effector_joint" type="fixed">
    <origin xyz="0 0.03 -0.17" rpy="0 0 0" />
    <parent link="zarm_r7_link" />
    <child link="zarm_r7_end_effector" />
  </joint>
  </robot>