<?xml version='1.0' encoding='utf-8'?>
<mujoco model="biped_s63">
  <compiler angle="radian" meshdir="../meshes/" />
  <size njmax="500" nconmax="100" />

  <asset>
    <mesh name="base_link" file="chassis.STL"/>
    <mesh name="wheel_left_front" file="wheel_left_front.STL"/>
    <mesh name="wheel_right_front" file="wheel_right_front.STL"/>
    <mesh name="wheel_left_behind" file="wheel_left_behind.STL"/>
    <mesh name="wheel_right_behind" file="wheel_right_behind.STL"/>
    <mesh name="knee_link" file="knee_link.STL"/>
    <mesh name="leg_Link" file="knee_pitch.STL"/>
    <mesh name="waist_pitch_Link" file="leg_pitch.STL"/>
    <mesh name="waist_yaw_Link" file="waist_pitch.STL"/>
    <mesh name="torso" file="torso.STL"/>
    <mesh name="l_arm_pitch" file="l_arm_pitch.STL"/>
    <mesh name="l_arm_roll" file="l_arm_roll.STL"/>
    <mesh name="l_arm_yaw" file="l_arm_yaw.STL"/>
    <mesh name="l_forearm" file="l_forearm.STL"/>
    <mesh name="l_hand_yaw" file="l_hand_yaw.STL"/>
    <mesh name="l_hand_roll" file="l_hand_roll.STL"/>
    <mesh name="l_hand_pitch_noHand" file="l_hand_pitch_noHand.STL"/>
    <mesh name="r_arm_pitch" file="r_arm_pitch.STL"/>
    <mesh name="r_arm_roll" file="r_arm_roll.STL"/>
    <mesh name="r_arm_yaw" file="r_arm_yaw.STL"/>
    <mesh name="r_forearm" file="r_forearm.STL"/>
    <mesh name="r_hand_yaw" file="r_hand_yaw.STL"/>
    <mesh name="r_hand_roll" file="r_hand_roll.STL"/>
    <mesh name="r_hand_pitch_noHand" file="r_hand_pitch_noHand.STL"/>
    <mesh name="head_yaw" file="head_yaw.STL"/>
    <mesh name="head_pitch" file="head_pitch.STL"/>
    <mesh name="head_camera_base" file="head_camera_base.STL"/>
    <mesh name="head_camera_depth" file="head_camera_depth.STL"/>
    <mesh name="head_radar" file="head_radar.STL"/>
  </asset>

  <worldbody>
    <body name="base_link" pos="0 0 0">
      <freejoint />
      <site name="imu" pos="0 0 0" />
      <inertial pos="0.00668334 -0.00289928 0.184488" quat="0.0158084 0.685869 -0.0123296 0.727448" mass="400.745" diaginertia="9.20505 7.1803 7.02738"/>
      <geom type="mesh" contype="0" conaffinity="0" group="1" density="0" rgba="1 1 1 1" mesh="base_link"/>
      <geom pos="0.23865 0.23865 0.13035" quat="0.923879 0 0 0.382684" type="mesh" contype="0" conaffinity="0" group="1" density="0" rgba="1 1 1 1" mesh="wheel_left_front"/>
      <geom pos="0.23865 -0.23865 0.13035" quat="0.923879 0 0 -0.382684" type="mesh" contype="0" conaffinity="0" group="1" density="0" rgba="1 1 1 1" mesh="wheel_right_front"/>
      <geom pos="-0.23865 0.23865 0.13035" quat="0.382681 0 0 0.923881" type="mesh" contype="0" conaffinity="0" group="1" density="0" rgba="1 1 1 1" mesh="wheel_left_behind"/>
      <geom pos="-0.23865 -0.23865 0.13035" quat="0.382681 0 0 -0.923881" type="mesh" contype="0" conaffinity="0" group="1" density="0" rgba="1 1 1 1" mesh="wheel_right_behind"/>
      <geom pos="0.093 0 0.30085" type="mesh" contype="0" conaffinity="0" group="1" density="0" rgba="1 1 1 1" mesh="knee_link"/>
      <body name="LF_wheel_yaw" pos="0.23865 0.23865 0.13035">
        <inertial pos="0 0 0" mass="0.0001" diaginertia="0.0000001 0.0000001 0.0000001"/>
        <joint name="LF_wheel_yaw_joint" pos="0 0 0" axis="0 0 1"/>
        <body name="LF_wheel_pitch">
          <inertial pos="0 0 0" mass="0.0001" diaginertia="0.0000001 0.0000001 0.0000001"/>
          <joint name="LF_wheel_pitch_joint" pos="0 0 0" axis="0 1 0"/>
          <geom size="0.13035 0.015" quat="0.707107 0.707107 0 0" type="cylinder" rgba="1 1 1 0" friction="3.0 0.001 0.001"/>
        </body>
      </body>
      <body name="RF_wheel_yaw" pos="0.23865 -0.23865 0.13035">
        <inertial pos="0 0 0" mass="0.0001" diaginertia="0.0000001 0.0000001 0.0000001"/>
        <joint name="RF_wheel_yaw_joint" pos="0 0 0" axis="0 0 1"/>
        <body name="RF_wheel_pitch">
          <inertial pos="0 0 0" mass="0.0001" diaginertia="0.0000001 0.0000001 0.0000001"/>
          <joint name="RF_wheel_pitch_joint" pos="0 0 0" axis="0 1 0"/>
          <geom size="0.13035 0.015" quat="0.707107 0.707107 0 0" type="cylinder" rgba="1 1 1 0" friction="3.0 0.001 0.001"/>
        </body>
      </body>
      <body name="LB_wheel_yaw" pos="-0.23865 0.23865 0.13035">
        <inertial pos="0 0 0" mass="0.0001" diaginertia="0.0000001 0.0000001 0.0000001"/>
        <joint name="LB_wheel_yaw_joint" pos="0 0 0" axis="0 0 1"/>
        <body name="LB_wheel_pitch">
          <inertial pos="0 0 0" mass="0.0001" diaginertia="0.0000001 0.0000001 0.0000001"/>
          <joint name="LB_wheel_pitch_joint" pos="0 0 0" axis="0 1 0"/>
          <geom size="0.13035 0.015" quat="0.707107 0.707107 0 0" type="cylinder" rgba="1 1 1 0" friction="3.0 0.001 0.001"/>
        </body>
      </body>
      <body name="RB_wheel_yaw" pos="-0.23865 -0.23865 0.13035">
        <inertial pos="0 0 0" mass="0.0001" diaginertia="0.00000001 0.0000001 0.0000001"/>
        <joint name="RB_wheel_yaw_joint" pos="0 0 0" axis="0 0 1"/>
        <body name="RB_wheel_pitch">
          <inertial pos="0 0 0" mass="0.0001" diaginertia="0.0000001 0.0000001 0.0000001"/>
          <joint name="RB_wheel_pitch_joint" pos="0 0 0" axis="0 1 0"/>
          <geom size="0.13035 0.015" quat="0.707107 0.707107 0 0" type="cylinder" rgba="1 1 1 0" friction="3.0 0.001 0.001"/>
        </body>
      </body>
      <body name="knee_link" pos="0.093 0 0.40635">
        <inertial pos="-0.296095 -0.00168429 0.116823" quat="-0.00307894 0.824747 0.0102345 0.565401" mass="13.6071" diaginertia="0.513757 0.472131 0.0878834"/>
        <joint name="knee_joint" pos="0 0 0" axis="0 1 0" range="0 1.44862" actuatorfrcrange="-668.53 668.53" damping="0.0"/>
        <geom type="mesh" contype="0" conaffinity="0" group="1" density="0" rgba="1 1 1 1" mesh="leg_Link"/>
        <body name="leg_link" pos="-0.46521 0 0.18325">
          <inertial pos="0.322411 0.0106839 0.0865922" quat="0.571137 0.442637 0.417779 0.55076" mass="9.43091" diaginertia="0.368084 0.35008 0.0294068"/>
          <joint name="leg_joint" pos="0 0 0" axis="0 1 0" range="-2.80998 0" actuatorfrcrange="-668.53 668.53"/>
          <geom type="mesh" contype="0" conaffinity="0" group="1" density="0" rgba="1 1 1 1" mesh="waist_pitch_Link"/>
          <body name="waist_pitch_link" pos="0.48296 0 0.12941">
            <inertial pos="-0.0019613 0.00090053 0.123171" quat="0.998165 0.0573327 0.00693553 -0.0181869" mass="8.15312" diaginertia="0.0695909 0.0570014 0.0422965"/>
            <joint name="waist_pitch_joint" pos="0 0 0" axis="0 1 0" range="-0.15708 2.98451" actuatorfrcrange="-618.48 618.48" damping="0.0"/>
            <geom type="mesh" contype="0" conaffinity="0" group="1" density="0" rgba="1 1 1 1" mesh="waist_yaw_Link"/>
            <body name="waist_yaw_link" pos="0 0 0.25">
              <inertial pos="-0.002057 -0.00093254 0.157765" quat="0.717601 0.696386 0.00786495 -0.00568946" mass="12.642" diaginertia="0.230193 0.159774 0.147154"/>
              <joint name="waist_yaw_joint" pos="0 0 0" axis="0 0 1" range="-3.14159 3.14159" actuatorfrcrange="-618.48 618.48" damping="0.0"/>
              <geom type="mesh" contype="0" conaffinity="0" group="1" density="0" rgba="1 1 1 1" mesh="torso"/>
              <body name="zarm_l1_link" pos="0 0.253 0.227">
                <inertial pos="0.00140078 -0.010235 -0.00030514" quat="0.708449 0.7049 -0.00774269 -0.034" mass="1.01296" diaginertia="0.00147543 0.00144282 0.000964459"/>
                <joint name="zarm_l1_joint" pos="0 0 0" axis="0 1 0" range="-3.14159 1.5708" actuatorfrcrange="-85 85" damping="0.0"/>
                <geom type="mesh" contype="0" conaffinity="0" group="1" density="0" rgba="1 1 1 1" mesh="l_arm_pitch"/>
                <body name="zarm_l2_link">
                  <inertial pos="-0.00070214 -6.01e-06 -0.0462779" quat="0.703645 0.0708044 0.070601 0.703482" mass="0.437889" diaginertia="0.00128467 0.000885488 0.000770102"/>
                  <joint name="zarm_l2_joint" pos="0 0 0" axis="1 0 0" range="-0.349066 3.49066" actuatorfrcrange="-75 75" damping="0.0"/>
                  <geom type="mesh" contype="0" conaffinity="0" group="1" density="0" rgba="1 1 1 1" mesh="l_arm_roll"/>
                  <body name="zarm_l3_link">
                    <inertial pos="0.00964741 0.00319323 -0.229195" quat="0.938551 0.0522811 -0.059591 -0.335912" mass="1.83545" diaginertia="0.00743246 0.00738062 0.00181201"/>
                    <joint name="zarm_l3_joint" pos="0 0 0" axis="0 0 1" range="-1.48353 1.48353" actuatorfrcrange="-57 57" damping="0.0"/>
                    <geom type="mesh" contype="0" conaffinity="0" group="1" density="0" rgba="1 1 1 1" mesh="l_arm_yaw"/>
                    <body name="zarm_l4_link" pos="0.02 0 -0.2837">
                      <inertial pos="-0.0182629 0.00208235 -0.0669584" quat="0.996082 -0.0410279 0.0783038 -0.00235936" mass="0.657704" diaginertia="0.00157685 0.00134433 0.00068768"/>
                      <joint name="zarm_l4_joint" pos="0 0 0" axis="0 1 0" range="-2.61799 0" actuatorfrcrange="-75 75" damping="0.0"/>
                      <geom type="mesh" contype="0" conaffinity="0" group="1" density="0" rgba="1 1 1 1" mesh="l_forearm"/>
                      <body name="zarm_l5_link" pos="-0.02 0 -0.1195">
                        <inertial pos="-0.00889277 1.406e-05 -0.0568964" quat="0.691897 0.147131 0.14938 0.690881" mass="0.678784" diaginertia="0.00105528 0.000734737 0.000564267"/>
                        <joint name="zarm_l5_joint" pos="0 0 0" axis="0 0 1" range="-1.5708 1.5708" actuatorfrcrange="-14.1 14.1" damping="0.0"/>
                        <geom type="mesh" contype="0" conaffinity="0" group="1" density="0" rgba="1 1 1 1" mesh="l_hand_yaw"/>
                        <body name="zarm_l6_link" pos="0 0 -0.114">
                          <inertial pos="-0.0017411 0.00664955 -0.0143008" quat="0.192371 0.701835 0.263078 0.633412" mass="0.512305" diaginertia="0.000316031 0.000292605 0.000195864"/>
                          <joint name="zarm_l6_joint" pos="0 0 0" axis="1 0 0" range="-1.309 0.698132" actuatorfrcrange="-14.1 14.1" damping="0.0"/>
                          <geom type="mesh" contype="0" conaffinity="0" group="1" density="0" rgba="1 1 1 1" mesh="l_hand_roll"/>
                          <body name="zarm_l7_link" pos="0 0 -0.021">
                            <inertial pos="0 0.00872986 -0.0838155" quat="0.707107 -0.000144762 0.000144762 0.707107" mass="0.737924" diaginertia="0.00133629 0.00112896 0.000373472"/>
                            <joint name="zarm_l7_joint" pos="0 0 0" axis="0 1 0" range="-0.698132 0.698132" actuatorfrcrange="-14.1 14.1" damping="0.0"/>
                            <geom type="mesh" contype="0" conaffinity="0" group="1" density="0" rgba="1 1 1 1" mesh="l_hand_pitch_noHand"/>
                            <geom size="0.005" pos="0 0 -0.17"/>
                            <body name="zarm_l7_end_effector" pos="0 0 -0.17">
                              <site name="l_arm_ft_frame" pos="0 0 0" size="0.01 0.005 0.01" rgba="1 0 0 1" type="box" group="1"/>
                              <geom type="box" size="0.01 0.005 0.02" contype="1" conaffinity="1"/>              
                            </body>
                          </body>
                        </body>
                      </body>
                    </body>
                  </body>
                </body>
              </body>
              <body name="zarm_r1_link" pos="0 -0.253 0.227">
                <inertial pos="0.00140078 0.010235 -0.00030514" quat="0.7049 0.708449 0.034 0.00774269" mass="1.01296" diaginertia="0.00147543 0.00144282 0.000964459"/>
                <joint name="zarm_r1_joint" pos="0 0 0" axis="0 1 0" range="-3.14159 1.5708" actuatorfrcrange="-85 85" damping="0.0"/>
                <geom type="mesh" contype="0" conaffinity="0" group="1" density="0" rgba="1 1 1 1" mesh="r_arm_pitch"/>
                <body name="zarm_r2_link">
                  <inertial pos="-0.00070214 6.01e-06 -0.0462779" quat="0.703482 0.070601 0.0708044 0.703645" mass="0.437889" diaginertia="0.00128467 0.000885488 0.000770102"/>
                  <joint name="zarm_r2_joint" pos="0 0 0" axis="1 0 0" range="-3.49066 0.349066" actuatorfrcrange="-75 75" damping="0.0"/>
                  <geom type="mesh" contype="0" conaffinity="0" group="1" density="0" rgba="1 1 1 1" mesh="r_arm_roll"/>
                  <body name="zarm_r3_link">
                    <inertial pos="0.00964741 -0.00319323 -0.229195" quat="0.938551 -0.0522811 -0.059591 0.335912" mass="1.83545" diaginertia="0.00743246 0.00738062 0.00181201"/>
                    <joint name="zarm_r3_joint" pos="0 0 0" axis="0 0 1" range="-1.48353 1.48353" actuatorfrcrange="-57 57" damping="0.0"/>
                    <geom type="mesh" contype="0" conaffinity="0" group="1" density="0" rgba="1 1 1 1" mesh="r_arm_yaw"/>
                    <body name="zarm_r4_link" pos="0.02 0 -0.2837">
                      <inertial pos="-0.0182629 -0.00208235 -0.0669584" quat="0.996082 0.0410279 0.0783038 0.00235936" mass="0.657704" diaginertia="0.00157685 0.00134433 0.00068768"/>
                      <joint name="zarm_r4_joint" pos="0 0 0" axis="0 1 0" range="-2.61799 0" actuatorfrcrange="-75 75" damping="0.0"/>
                      <geom type="mesh" contype="0" conaffinity="0" group="1" density="0" rgba="1 1 1 1" mesh="r_forearm"/>
                      <body name="zarm_r5_link" pos="-0.02 0 -0.1195">
                        <inertial pos="-0.00889277 -1.406e-05 -0.0568964" quat="0.690881 0.14938 0.147131 0.691897" mass="0.678784" diaginertia="0.00105528 0.000734737 0.000564267"/>
                        <joint name="zarm_r5_joint" pos="0 0 0" axis="0 0 1" range="-1.5708 1.5708" actuatorfrcrange="-14.1 14.1" damping="0.0"/>
                        <geom type="mesh" contype="0" conaffinity="0" group="1" density="0" rgba="1 1 1 1" mesh="r_hand_yaw"/>
                        <body name="zarm_r6_link" pos="0 0 -0.114">
                          <inertial pos="-0.0017411 -0.00664955 -0.0143008" quat="-0.192371 0.701835 -0.263078 0.633412" mass="0.512305" diaginertia="0.000316031 0.000292605 0.000195864"/>
                          <joint name="zarm_r6_joint" pos="0 0 0" axis="1 0 0" range="-0.698132 1.309" actuatorfrcrange="-14.1 14.1" damping="0.0"/>
                          <geom type="mesh" contype="0" conaffinity="0" group="1" density="0" rgba="1 1 1 1" mesh="r_hand_roll"/>
                          <body name="zarm_r7_link" pos="0 0 -0.021">
                            <inertial pos="0 -0.00870239 -0.0837024" quat="0.707107 0.000147101 -0.000147101 0.707107" mass="0.737924" diaginertia="0.00131998 0.00111231 0.000374213"/>
                            <joint name="zarm_r7_joint" pos="0 0 0" axis="0 1 0" range="-0.698132 0.698132" actuatorfrcrange="-14.1 14.1" damping="0.0"/>
                            <geom type="mesh" contype="0" conaffinity="0" group="1" density="0" rgba="1 1 1 1" mesh="r_hand_pitch_noHand"/>
                            <geom size="0.005" pos="0 0 -0.17"/>
                            <!-- 右手末端执行器 -->
                            <body name="zarm_r7_end_effector" pos="0 0 -0.17">
                              <site name="r_arm_ft_frame" pos="0 0 0" size="0.01 0.005 0.01" rgba="0 0 1 1" type="box" group="1"/>
                              <geom type="box" size="0.01 0.005 0.02" contype="1" conaffinity="1"/>  
                            </body>
                          </body>
                        </body>
                      </body>
                    </body>
                  </body>
                </body>
              </body>
              <body name="zhead_1_link" pos="0 0 0.43485">
                <inertial pos="-0.00029696 -0.0027932 -0.0376999" quat="0.999679 0.0249396 0.00153832 0.00413552" mass="0.816954" diaginertia="0.00206265 0.00192336 0.000654121"/>
                <joint name="zhead_1_joint" pos="0 0 0" axis="0 0 1" range="-1.57 1.57" actuatorfrcrange="-15.5 15.5" damping="0.0"/>
                <geom type="mesh" contype="0" conaffinity="0" group="1" density="0" rgba="1 1 1 1" mesh="head_yaw"/>
                <geom pos="0 0 -0.078453" quat="1 0 0 0" type="mesh" contype="0" conaffinity="0" group="1" density="0" rgba="0.611765 0.658824 0.670588 1" mesh="head_radar"/>
                <body name="zhead_2_link">
                  <inertial pos="0.0352257 0.00045985 0.0449437" quat="0.0539262 0.840844 0.0771762 0.533027" mass="0.823797" diaginertia="0.00481577 0.00472128 0.00406429"/>
                  <joint name="zhead_2_joint" pos="0 0 0" axis="0 1 0" range="-0.526 0.526" actuatorfrcrange="-14.5 14.5" damping="0.0"/>
                  <geom type="mesh" contype="0" conaffinity="0" group="1" density="0" rgba="1 1 1 1" mesh="head_pitch"/>
                  <geom pos="0.099619 0 0.032844" quat="0.985534 0 0.169478 0" type="mesh" contype="0" conaffinity="0" group="1" density="0" rgba="1 1 1 1" mesh="head_camera_base"/>
                  <geom pos="0.115442 0.0475 0.0424195" quat="0.985534 0 0.169478 0" type="mesh" contype="0" conaffinity="0" group="1" density="0" rgba="1 1 1 1" mesh="head_camera_depth"/>
                </body>
              </body>
            </body>
          </body>
        </body>
      </body>
    </body>
  </worldbody>
  <actuator>
    <motor gear="1" joint="LF_wheel_yaw_joint"   name="LF_wheel_yaw_joint_motor"   ctrllimited="true" ctrlrange="-40 40"  />
    <motor gear="1" joint="LF_wheel_pitch_joint" name="LF_wheel_pitch_joint_motor" ctrllimited="true" ctrlrange="-40 40"  />
    <motor gear="1" joint="RF_wheel_yaw_joint"   name="RF_wheel_yaw_joint_motor"   ctrllimited="true" ctrlrange="-40 40"  />
    <motor gear="1" joint="RF_wheel_pitch_joint" name="RF_wheel_pitch_joint_motor" ctrllimited="true" ctrlrange="-40 40"  />
    <motor gear="1" joint="LB_wheel_yaw_joint"   name="LB_wheel_yaw_joint_motor"   ctrllimited="true" ctrlrange="-40 40"  />
    <motor gear="1" joint="LB_wheel_pitch_joint" name="LB_wheel_pitch_joint_motor" ctrllimited="true" ctrlrange="-40 40"  />
    <motor gear="1" joint="RB_wheel_yaw_joint"   name="RB_wheel_yaw_joint_motor"   ctrllimited="true" ctrlrange="-40 40"  />
    <motor gear="1" joint="RB_wheel_pitch_joint" name="RB_wheel_pitch_joint_motor" ctrllimited="true" ctrlrange="-40 40"  />

    <motor gear="1" joint="knee_joint" name="knee_joint_motor" ctrllimited="true" ctrlrange="-668.53 668.53" />
    <motor gear="1" joint="leg_joint" name="leg_joint_motor" ctrllimited="true" ctrlrange="-668.53 668.53" />
    <motor gear="1" joint="waist_pitch_joint" name="waist_pitch_joint_motor" ctrllimited="true" ctrlrange="-618.48 618.48" />
    <motor gear="1" joint="waist_yaw_joint" name="waist_yaw_joint_motor" ctrllimited="true" ctrlrange="-618.48 618.48" />
    <motor gear="1" joint="zarm_l1_joint" name="zarm_l1_joint_motor" ctrllimited="true" ctrlrange="-85 85" />
    <motor gear="1" joint="zarm_l2_joint" name="zarm_l2_joint_motor" ctrllimited="true" ctrlrange="-75 75" />
    <motor gear="1" joint="zarm_l3_joint" name="zarm_l3_joint_motor" ctrllimited="true" ctrlrange="-57 57" />
    <motor gear="1" joint="zarm_l4_joint" name="zarm_l4_joint_motor" ctrllimited="true" ctrlrange="-75 75" />
    <motor gear="1" joint="zarm_l5_joint" name="zarm_l5_joint_motor" ctrllimited="true" ctrlrange="-14.1 14.1" />
    <motor gear="1" joint="zarm_l6_joint" name="zarm_l6_joint_motor" ctrllimited="true" ctrlrange="-14.1 14.1" />
    <motor gear="1" joint="zarm_l7_joint" name="zarm_l7_joint_motor" ctrllimited="true" ctrlrange="-14.1 14.1" />
    <motor gear="1" joint="zarm_r1_joint" name="zarm_r1_joint_motor" ctrllimited="true" ctrlrange="-85 85" />
    <motor gear="1" joint="zarm_r2_joint" name="zarm_r2_joint_motor" ctrllimited="true" ctrlrange="-75 75" />
    <motor gear="1" joint="zarm_r3_joint" name="zarm_r3_joint_motor" ctrllimited="true" ctrlrange="-57 57" />
    <motor gear="1" joint="zarm_r4_joint" name="zarm_r4_joint_motor" ctrllimited="true" ctrlrange="-75 75" />
    <motor gear="1" joint="zarm_r5_joint" name="zarm_r5_joint_motor" ctrllimited="true" ctrlrange="-14.1 14.1" />
    <motor gear="1" joint="zarm_r6_joint" name="zarm_r6_joint_motor" ctrllimited="true" ctrlrange="-14.1 14.1" />
    <motor gear="1" joint="zarm_r7_joint" name="zarm_r7_joint_motor" ctrllimited="true" ctrlrange="-14.1 14.1" />
    <motor gear="1" joint="zhead_1_joint" name="zhead_1_joint_motor" ctrllimited="true" ctrlrange="-14.1 14.1" />
    <motor gear="1" joint="zhead_2_joint" name="zhead_2_joint_motor" ctrllimited="true" ctrlrange="-14.1 14.1" />
  </actuator>
  <sensor>
    <accelerometer name="BodyAcc" site="imu" />
    <velocimeter name="BodyVel" site="imu" />
    <gyro name="BodyGyro" site="imu" />
    <framepos name="BodyPos" objtype="site" objname="imu" />
    <framequat name="BodyQuat" objtype="site" objname="imu" />
<force name="l_arm_force" site="l_arm_ft_frame"/>
    <torque name="l_arm_torque" site="l_arm_ft_frame"/>
    <force name="r_arm_force" site="r_arm_ft_frame"/>
    <torque name="r_arm_torque" site="r_arm_ft_frame"/>

    <jointpos name="LF_wheel_yaw_joint_pos"   joint="LF_wheel_yaw_joint"   />
    <jointpos name="LF_wheel_pitch_joint_pos" joint="LF_wheel_pitch_joint" />
    <jointpos name="RF_wheel_yaw_joint_pos"   joint="RF_wheel_yaw_joint"   />
    <jointpos name="RF_wheel_pitch_joint_pos" joint="RF_wheel_pitch_joint" />
    <jointpos name="LB_wheel_yaw_joint_pos"   joint="LB_wheel_yaw_joint"   />
    <jointpos name="LB_wheel_pitch_joint_pos" joint="LB_wheel_pitch_joint" />
    <jointpos name="RB_wheel_yaw_joint_pos"   joint="RB_wheel_yaw_joint"   />
    <jointpos name="RB_wheel_pitch_joint_pos" joint="RB_wheel_pitch_joint" />

    <jointpos name="knee_joint_pos" joint="knee_joint" />
    <jointpos name="leg_joint_pos" joint="leg_joint" />
    <jointpos name="waist_pitch_joint_pos" joint="waist_pitch_joint" />
    <jointpos name="waist_yaw_joint_pos" joint="waist_yaw_joint" />
    <jointpos name="zarm_l1_joint_pos" joint="zarm_l1_joint" />
    <jointpos name="zarm_l2_joint_pos" joint="zarm_l2_joint" />
    <jointpos name="zarm_l3_joint_pos" joint="zarm_l3_joint" />
    <jointpos name="zarm_l4_joint_pos" joint="zarm_l4_joint" />
    <jointpos name="zarm_l5_joint_pos" joint="zarm_l5_joint" />
    <jointpos name="zarm_l6_joint_pos" joint="zarm_l6_joint" />
    <jointpos name="zarm_l7_joint_pos" joint="zarm_l7_joint" />
    <jointpos name="zarm_r1_joint_pos" joint="zarm_r1_joint" />
    <jointpos name="zarm_r2_joint_pos" joint="zarm_r2_joint" />
    <jointpos name="zarm_r3_joint_pos" joint="zarm_r3_joint" />
    <jointpos name="zarm_r4_joint_pos" joint="zarm_r4_joint" />
    <jointpos name="zarm_r5_joint_pos" joint="zarm_r5_joint" />
    <jointpos name="zarm_r6_joint_pos" joint="zarm_r6_joint" />
    <jointpos name="zarm_r7_joint_pos" joint="zarm_r7_joint" />
    <jointpos name="zhead_1_joint_pos" joint="zhead_1_joint" />
    <jointpos name="zhead_2_joint_pos" joint="zhead_2_joint" />

    <jointvel name="LF_wheel_yaw_joint_vel"   joint="LF_wheel_yaw_joint"   />
    <jointvel name="LF_wheel_pitch_joint_vel" joint="LF_wheel_pitch_joint" />
    <jointvel name="RF_wheel_yaw_joint_vel"   joint="RF_wheel_yaw_joint"   />
    <jointvel name="RF_wheel_pitch_joint_vel" joint="RF_wheel_pitch_joint" />
    <jointvel name="LB_wheel_yaw_joint_vel"   joint="LB_wheel_yaw_joint"   />
    <jointvel name="LB_wheel_pitch_joint_vel" joint="LB_wheel_pitch_joint" />
    <jointvel name="RB_wheel_yaw_joint_vel"   joint="RB_wheel_yaw_joint"   />
    <jointvel name="RB_wheel_pitch_joint_vel" joint="RB_wheel_pitch_joint" />

    <jointvel name="knee_joint_vel" joint="knee_joint" />
    <jointvel name="leg_joint_vel" joint="leg_joint" />
    <jointvel name="waist_pitch_joint_vel" joint="waist_pitch_joint" />
    <jointvel name="waist_yaw_joint_vel" joint="waist_yaw_joint" />
    <jointvel name="zarm_l1_joint_vel" joint="zarm_l1_joint" />
    <jointvel name="zarm_l2_joint_vel" joint="zarm_l2_joint" />
    <jointvel name="zarm_l3_joint_vel" joint="zarm_l3_joint" />
    <jointvel name="zarm_l4_joint_vel" joint="zarm_l4_joint" />
    <jointvel name="zarm_l5_joint_vel" joint="zarm_l5_joint" />
    <jointvel name="zarm_l6_joint_vel" joint="zarm_l6_joint" />
    <jointvel name="zarm_l7_joint_vel" joint="zarm_l7_joint" />
    <jointvel name="zarm_r1_joint_vel" joint="zarm_r1_joint" />
    <jointvel name="zarm_r2_joint_vel" joint="zarm_r2_joint" />
    <jointvel name="zarm_r3_joint_vel" joint="zarm_r3_joint" />
    <jointvel name="zarm_r4_joint_vel" joint="zarm_r4_joint" />
    <jointvel name="zarm_r5_joint_vel" joint="zarm_r5_joint" />
    <jointvel name="zarm_r6_joint_vel" joint="zarm_r6_joint" />
    <jointvel name="zarm_r7_joint_vel" joint="zarm_r7_joint" />
    <jointvel name="zhead_1_joint_vel" joint="zhead_1_joint" />
    <jointvel name="zhead_2_joint_vel" joint="zhead_2_joint" />
  </sensor>
</mujoco>
